Workbook

Sheet Instructions
A1: Compliance Batch Framework - Test Cases
A2: Framework 0.3.67 (Airflow / Teradata), CMSUNIV DEV. Source: airflow_resources/docs/TEST_CASES.md
A4: How to use
A5: 1. Check the prerequisites (sheet Prerequisites) and prepare the test files (sheet Test Data).
A6: 2. Run each case on sheet Test Cases: setup, steps, then compare with the expected result.
A7: 3. Per case: run the Setup SQL (if any), run the Job to Execute, run the Verification SQL, compare with the Expected Result.
A8: 4. Fill in the yellow columns only: Status, Actual Result, Tester, Test Date, DAG Run ID, Batch ID / Load ID, Defect / Comments.
A9: 5. Status values: Not Run, Pass, Fail, Blocked, N/A (drop-down). Sheet Summary counts them per area automatically.
A10: 6. More queries Q1 - Q12 are on sheet Queries; replace <batch>, <table> and dates with those of the case.
A11: 7. 'Trigger X with {...}' = Airflow -> the DAG -> Trigger DAG w/ config -> paste the JSON.
A12: 8. Replace <batch>, <table>, <Req_ID>, <you> in the SQL and JSON. Setup changes marked 'revert after' must be undone after the case.
A13: 9. Do not run in PROD; use test files with dummy member data only.
A15: Example of a filled-in row (format only)
A16: ID | B16: Status | C16: Actual Result | D16: Tester | E16: Test Date | F16: DAG Run ID | G16: Batch ID / Load ID | H16: Defect / Comments
A17: BC-01 | B17: Pass | C17: 13 DLY batches, one row per source, dates 2026-10-25 | D17: jdoe | E17: 2026-10-26 | F17: manual__2026-10-26T11:02:13 | G17: 20261026_CMSUNIV_ODAG3_DLY | H17: -

Sheet Summary
A1: Area code | B1: Area | C1: Total | D1: Pass | E1: Fail | F1: Blocked | G1: N/A | H1: Not Run | I1: % Executed | J1: % Passed of executed
A2: CFG | B2: Setup and configuration | C2: =COUNTIF('Test Cases'!$A$2:$A$186,"CFG-*") | D2: =COUNTIFS('Test Cases'!$A$2:$A$186,"CFG-*",'Test Cases'!$K$2:$K$186,"Pass") | E2: =COUNTIFS('Test Cases'!$A$2:$A$186,"CFG-*",'Test Cases'!$K$2:$K$186,"Fail") | F2: =COUNTIFS('Test Cases'!$A$2:$A$186,"CFG-*",'Test Cases'!$K$2:$K$186,"Blocked") | G2: =COUNTIFS('Test Cases'!$A$2:$A$186,"CFG-*",'Test Cases'!$K$2:$K$186,"N/A") | H2: =COUNTIFS('Test Cases'!$A$2:$A$186,"CFG-*",'Test Cases'!$K$2:$K$186,"Not Run") | I2: =IF(C2=0,0,(D2+E2+F2+G2)/C2) | J2: =IF((D2+E2)=0,0,D2/(D2+E2))
A3: BC | B3: Batch creation | C3: =COUNTIF('Test Cases'!$A$2:$A$186,"BC-*") | D3: =COUNTIFS('Test Cases'!$A$2:$A$186,"BC-*",'Test Cases'!$K$2:$K$186,"Pass") | E3: =COUNTIFS('Test Cases'!$A$2:$A$186,"BC-*",'Test Cases'!$K$2:$K$186,"Fail") | F3: =COUNTIFS('Test Cases'!$A$2:$A$186,"BC-*",'Test Cases'!$K$2:$K$186,"Blocked") | G3: =COUNTIFS('Test Cases'!$A$2:$A$186,"BC-*",'Test Cases'!$K$2:$K$186,"N/A") | H3: =COUNTIFS('Test Cases'!$A$2:$A$186,"BC-*",'Test Cases'!$K$2:$K$186,"Not Run") | I3: =IF(C3=0,0,(D3+E3+F3+G3)/C3) | J3: =IF((D3+E3)=0,0,D3/(D3+E3))
A4: IN | B4: Ad-hoc requests | C4: =COUNTIF('Test Cases'!$A$2:$A$186,"IN-*") | D4: =COUNTIFS('Test Cases'!$A$2:$A$186,"IN-*",'Test Cases'!$K$2:$K$186,"Pass") | E4: =COUNTIFS('Test Cases'!$A$2:$A$186,"IN-*",'Test Cases'!$K$2:$K$186,"Fail") | F4: =COUNTIFS('Test Cases'!$A$2:$A$186,"IN-*",'Test Cases'!$K$2:$K$186,"Blocked") | G4: =COUNTIFS('Test Cases'!$A$2:$A$186,"IN-*",'Test Cases'!$K$2:$K$186,"N/A") | H4: =COUNTIFS('Test Cases'!$A$2:$A$186,"IN-*",'Test Cases'!$K$2:$K$186,"Not Run") | I4: =IF(C4=0,0,(D4+E4+F4+G4)/C4) | J4: =IF((D4+E4)=0,0,D4/(D4+E4))
A5: FC | B5: File check | C5: =COUNTIF('Test Cases'!$A$2:$A$186,"FC-*") | D5: =COUNTIFS('Test Cases'!$A$2:$A$186,"FC-*",'Test Cases'!$K$2:$K$186,"Pass") | E5: =COUNTIFS('Test Cases'!$A$2:$A$186,"FC-*",'Test Cases'!$K$2:$K$186,"Fail") | F5: =COUNTIFS('Test Cases'!$A$2:$A$186,"FC-*",'Test Cases'!$K$2:$K$186,"Blocked") | G5: =COUNTIFS('Test Cases'!$A$2:$A$186,"FC-*",'Test Cases'!$K$2:$K$186,"N/A") | H5: =COUNTIFS('Test Cases'!$A$2:$A$186,"FC-*",'Test Cases'!$K$2:$K$186,"Not Run") | I5: =IF(C5=0,0,(D5+E5+F5+G5)/C5) | J5: =IF((D5+E5)=0,0,D5/(D5+E5))
A6: FL | B6: File load - staging and core | C6: =COUNTIF('Test Cases'!$A$2:$A$186,"FL-*") | D6: =COUNTIFS('Test Cases'!$A$2:$A$186,"FL-*",'Test Cases'!$K$2:$K$186,"Pass") | E6: =COUNTIFS('Test Cases'!$A$2:$A$186,"FL-*",'Test Cases'!$K$2:$K$186,"Fail") | F6: =COUNTIFS('Test Cases'!$A$2:$A$186,"FL-*",'Test Cases'!$K$2:$K$186,"Blocked") | G6: =COUNTIFS('Test Cases'!$A$2:$A$186,"FL-*",'Test Cases'!$K$2:$K$186,"N/A") | H6: =COUNTIFS('Test Cases'!$A$2:$A$186,"FL-*",'Test Cases'!$K$2:$K$186,"Not Run") | I6: =IF(C6=0,0,(D6+E6+F6+G6)/C6) | J6: =IF((D6+E6)=0,0,D6/(D6+E6))
A7: SL | B7: Internal sources | C7: =COUNTIF('Test Cases'!$A$2:$A$186,"SL-*") | D7: =COUNTIFS('Test Cases'!$A$2:$A$186,"SL-*",'Test Cases'!$K$2:$K$186,"Pass") | E7: =COUNTIFS('Test Cases'!$A$2:$A$186,"SL-*",'Test Cases'!$K$2:$K$186,"Fail") | F7: =COUNTIFS('Test Cases'!$A$2:$A$186,"SL-*",'Test Cases'!$K$2:$K$186,"Blocked") | G7: =COUNTIFS('Test Cases'!$A$2:$A$186,"SL-*",'Test Cases'!$K$2:$K$186,"N/A") | H7: =COUNTIFS('Test Cases'!$A$2:$A$186,"SL-*",'Test Cases'!$K$2:$K$186,"Not Run") | I7: =IF(C7=0,0,(D7+E7+F7+G7)/C7) | J7: =IF((D7+E7)=0,0,D7/(D7+E7))
A8: OV | B8: Overrides | C8: =COUNTIF('Test Cases'!$A$2:$A$186,"OV-*") | D8: =COUNTIFS('Test Cases'!$A$2:$A$186,"OV-*",'Test Cases'!$K$2:$K$186,"Pass") | E8: =COUNTIFS('Test Cases'!$A$2:$A$186,"OV-*",'Test Cases'!$K$2:$K$186,"Fail") | F8: =COUNTIFS('Test Cases'!$A$2:$A$186,"OV-*",'Test Cases'!$K$2:$K$186,"Blocked") | G8: =COUNTIFS('Test Cases'!$A$2:$A$186,"OV-*",'Test Cases'!$K$2:$K$186,"N/A") | H8: =COUNTIFS('Test Cases'!$A$2:$A$186,"OV-*",'Test Cases'!$K$2:$K$186,"Not Run") | I8: =IF(C8=0,0,(D8+E8+F8+G8)/C8) | J8: =IF((D8+E8)=0,0,D8/(D8+E8))
A9: EX | B9: Export load and extract | C9: =COUNTIF('Test Cases'!$A$2:$A$186,"EX-*") | D9: =COUNTIFS('Test Cases'!$A$2:$A$186,"EX-*",'Test Cases'!$K$2:$K$186,"Pass") | E9: =COUNTIFS('Test Cases'!$A$2:$A$186,"EX-*",'Test Cases'!$K$2:$K$186,"Fail") | F9: =COUNTIFS('Test Cases'!$A$2:$A$186,"EX-*",'Test Cases'!$K$2:$K$186,"Blocked") | G9: =COUNTIFS('Test Cases'!$A$2:$A$186,"EX-*",'Test Cases'!$K$2:$K$186,"N/A") | H9: =COUNTIFS('Test Cases'!$A$2:$A$186,"EX-*",'Test Cases'!$K$2:$K$186,"Not Run") | I9: =IF(C9=0,0,(D9+E9+F9+G9)/C9) | J9: =IF((D9+E9)=0,0,D9/(D9+E9))
A10: RU | B10: Data quality rules | C10: =COUNTIF('Test Cases'!$A$2:$A$186,"RU-*") | D10: =COUNTIFS('Test Cases'!$A$2:$A$186,"RU-*",'Test Cases'!$K$2:$K$186,"Pass") | E10: =COUNTIFS('Test Cases'!$A$2:$A$186,"RU-*",'Test Cases'!$K$2:$K$186,"Fail") | F10: =COUNTIFS('Test Cases'!$A$2:$A$186,"RU-*",'Test Cases'!$K$2:$K$186,"Blocked") | G10: =COUNTIFS('Test Cases'!$A$2:$A$186,"RU-*",'Test Cases'!$K$2:$K$186,"N/A") | H10: =COUNTIFS('Test Cases'!$A$2:$A$186,"RU-*",'Test Cases'!$K$2:$K$186,"Not Run") | I10: =IF(C10=0,0,(D10+E10+F10+G10)/C10) | J10: =IF((D10+E10)=0,0,D10/(D10+E10))
A11: CL | B11: Batch close | C11: =COUNTIF('Test Cases'!$A$2:$A$186,"CL-*") | D11: =COUNTIFS('Test Cases'!$A$2:$A$186,"CL-*",'Test Cases'!$K$2:$K$186,"Pass") | E11: =COUNTIFS('Test Cases'!$A$2:$A$186,"CL-*",'Test Cases'!$K$2:$K$186,"Fail") | F11: =COUNTIFS('Test Cases'!$A$2:$A$186,"CL-*",'Test Cases'!$K$2:$K$186,"Blocked") | G11: =COUNTIFS('Test Cases'!$A$2:$A$186,"CL-*",'Test Cases'!$K$2:$K$186,"N/A") | H11: =COUNTIFS('Test Cases'!$A$2:$A$186,"CL-*",'Test Cases'!$K$2:$K$186,"Not Run") | I11: =IF(C11=0,0,(D11+E11+F11+G11)/C11) | J11: =IF((D11+E11)=0,0,D11/(D11+E11))
A12: NT | B12: Notifications | C12: =COUNTIF('Test Cases'!$A$2:$A$186,"NT-*") | D12: =COUNTIFS('Test Cases'!$A$2:$A$186,"NT-*",'Test Cases'!$K$2:$K$186,"Pass") | E12: =COUNTIFS('Test Cases'!$A$2:$A$186,"NT-*",'Test Cases'!$K$2:$K$186,"Fail") | F12: =COUNTIFS('Test Cases'!$A$2:$A$186,"NT-*",'Test Cases'!$K$2:$K$186,"Blocked") | G12: =COUNTIFS('Test Cases'!$A$2:$A$186,"NT-*",'Test Cases'!$K$2:$K$186,"N/A") | H12: =COUNTIFS('Test Cases'!$A$2:$A$186,"NT-*",'Test Cases'!$K$2:$K$186,"Not Run") | I12: =IF(C12=0,0,(D12+E12+F12+G12)/C12) | J12: =IF((D12+E12)=0,0,D12/(D12+E12))
A13: AF | B13: Airflow behaviour | C13: =COUNTIF('Test Cases'!$A$2:$A$186,"AF-*") | D13: =COUNTIFS('Test Cases'!$A$2:$A$186,"AF-*",'Test Cases'!$K$2:$K$186,"Pass") | E13: =COUNTIFS('Test Cases'!$A$2:$A$186,"AF-*",'Test Cases'!$K$2:$K$186,"Fail") | F13: =COUNTIFS('Test Cases'!$A$2:$A$186,"AF-*",'Test Cases'!$K$2:$K$186,"Blocked") | G13: =COUNTIFS('Test Cases'!$A$2:$A$186,"AF-*",'Test Cases'!$K$2:$K$186,"N/A") | H13: =COUNTIFS('Test Cases'!$A$2:$A$186,"AF-*",'Test Cases'!$K$2:$K$186,"Not Run") | I13: =IF(C13=0,0,(D13+E13+F13+G13)/C13) | J13: =IF((D13+E13)=0,0,D13/(D13+E13))
A14: AD | B14: Admin commands | C14: =COUNTIF('Test Cases'!$A$2:$A$186,"AD-*") | D14: =COUNTIFS('Test Cases'!$A$2:$A$186,"AD-*",'Test Cases'!$K$2:$K$186,"Pass") | E14: =COUNTIFS('Test Cases'!$A$2:$A$186,"AD-*",'Test Cases'!$K$2:$K$186,"Fail") | F14: =COUNTIFS('Test Cases'!$A$2:$A$186,"AD-*",'Test Cases'!$K$2:$K$186,"Blocked") | G14: =COUNTIFS('Test Cases'!$A$2:$A$186,"AD-*",'Test Cases'!$K$2:$K$186,"N/A") | H14: =COUNTIFS('Test Cases'!$A$2:$A$186,"AD-*",'Test Cases'!$K$2:$K$186,"Not Run") | I14: =IF(C14=0,0,(D14+E14+F14+G14)/C14) | J14: =IF((D14+E14)=0,0,D14/(D14+E14))
A15: LG | B15: Logging and security | C15: =COUNTIF('Test Cases'!$A$2:$A$186,"LG-*") | D15: =COUNTIFS('Test Cases'!$A$2:$A$186,"LG-*",'Test Cases'!$K$2:$K$186,"Pass") | E15: =COUNTIFS('Test Cases'!$A$2:$A$186,"LG-*",'Test Cases'!$K$2:$K$186,"Fail") | F15: =COUNTIFS('Test Cases'!$A$2:$A$186,"LG-*",'Test Cases'!$K$2:$K$186,"Blocked") | G15: =COUNTIFS('Test Cases'!$A$2:$A$186,"LG-*",'Test Cases'!$K$2:$K$186,"N/A") | H15: =COUNTIFS('Test Cases'!$A$2:$A$186,"LG-*",'Test Cases'!$K$2:$K$186,"Not Run") | I15: =IF(C15=0,0,(D15+E15+F15+G15)/C15) | J15: =IF((D15+E15)=0,0,D15/(D15+E15))
A16: E2E | B16: End-to-end scenarios | C16: =COUNTIF('Test Cases'!$A$2:$A$186,"E2E-*") | D16: =COUNTIFS('Test Cases'!$A$2:$A$186,"E2E-*",'Test Cases'!$K$2:$K$186,"Pass") | E16: =COUNTIFS('Test Cases'!$A$2:$A$186,"E2E-*",'Test Cases'!$K$2:$K$186,"Fail") | F16: =COUNTIFS('Test Cases'!$A$2:$A$186,"E2E-*",'Test Cases'!$K$2:$K$186,"Blocked") | G16: =COUNTIFS('Test Cases'!$A$2:$A$186,"E2E-*",'Test Cases'!$K$2:$K$186,"N/A") | H16: =COUNTIFS('Test Cases'!$A$2:$A$186,"E2E-*",'Test Cases'!$K$2:$K$186,"Not Run") | I16: =IF(C16=0,0,(D16+E16+F16+G16)/C16) | J16: =IF((D16+E16)=0,0,D16/(D16+E16))
A17: UP | B17: Upgrade statements | C17: =COUNTIF('Test Cases'!$A$2:$A$186,"UP-*") | D17: =COUNTIFS('Test Cases'!$A$2:$A$186,"UP-*",'Test Cases'!$K$2:$K$186,"Pass") | E17: =COUNTIFS('Test Cases'!$A$2:$A$186,"UP-*",'Test Cases'!$K$2:$K$186,"Fail") | F17: =COUNTIFS('Test Cases'!$A$2:$A$186,"UP-*",'Test Cases'!$K$2:$K$186,"Blocked") | G17: =COUNTIFS('Test Cases'!$A$2:$A$186,"UP-*",'Test Cases'!$K$2:$K$186,"N/A") | H17: =COUNTIFS('Test Cases'!$A$2:$A$186,"UP-*",'Test Cases'!$K$2:$K$186,"Not Run") | I17: =IF(C17=0,0,(D17+E17+F17+G17)/C17) | J17: =IF((D17+E17)=0,0,D17/(D17+E17))
B18: Total | C18: =SUM(C2:C17) | D18: =SUM(D2:D17) | E18: =SUM(E2:E17) | F18: =SUM(F2:F17) | G18: =SUM(G2:G17) | H18: =SUM(H2:H17) | I18: =IF(C18=0,0,(D18+E18+F18+G18)/C18) | J18: =IF((D18+E18)=0,0,D18/(D18+E18))
A20: Counts update from the Status column of sheet Test Cases.

Sheet Test Cases
A1: ID | B1: Area | C1: Test Case | D1: Description | E1: Precondition | F1: Setup SQL | G1: Job to Execute | H1: Test Steps | I1: Verification SQL | J1: Expected Result | K1: Status | L1: Actual Result | M1: Tester | N1: Test Date | O1: DAG Run ID | P1: Batch ID / Load ID | Q1: Defect / Comments
A2: CFG-01 | B2: Setup and configuration | C2: Configuration valid | D2: python -m compliance_framework.cli validate-config on a worker | G2: Worker shell (TERADATA_* and FRAMEWORK_METADATA_SCHEMA=HSABC_DEV set): python -m compliance_framework.cli validate-config | H2: 1. Check the precondition 2. Prepare the input: python -m compliance_framework.cli validate-config on a worker 3. Run the job 4. Check the task log / step report 5. Compare with the expected result and record the outcome | J2: No ERROR except the known ones (Facets 210 until configured); WARNINGs read and accepted | K2: Not Run
A3: CFG-02 | B3: Setup and configuration | C3: Unknown run type in crosswalk | D3: Set a crosswalk Run_Ty to 'DLY,XYZ'; validate | F3: UPDATE HSABC_DEV.ComplianceDataSetSourceXwalk SET Run_Ty = 'DLY,XYZ' WHERE Project_Cd = 'CMSUNIV' AND Table_Nm = 'ODAG3' AND Src_ID = '51'; -- revert after: SET Run_Ty = 'DLY,MNT' | G3: Worker shell (TERADATA_* and FRAMEWORK_METADATA_SCHEMA=HSABC_DEV set): python -m compliance_framework.cli validate-config | H3: 1. Check the precondition and run the setup SQL 2. Prepare the input: Set a crosswalk Run_Ty to 'DLY,XYZ'; validate 3. Run the job 4. Check the task log / step report 5. Compare with the expected result and record the outcome 6. Revert the setup change | J3: XWALK_RUN_TYPE error naming XYZ; revert | K3: Not Run
A4: CFG-03 | B4: Setup and configuration | C4: Missing source config | D4: Crosswalk row for a source with no file / internal config | F4: UPDATE HSABC_DEV.ComplianceSourceFileConfig SET Active_Ind = 0 WHERE Project_Cd = 'CMSUNIV' AND Table_Nm = 'ODAG3' AND Src_ID = '51'; -- revert after: SET Active_Ind = 1 | G4: Worker shell (TERADATA_* and FRAMEWORK_METADATA_SCHEMA=HSABC_DEV set): python -m compliance_framework.cli validate-config | H4: 1. Check the precondition and run the setup SQL 2. Prepare the input: Crosswalk row for a source with no file / internal config 3. Run the job 4. Check the task log / step report 5. Compare with the expected result and record the outcome 6. Revert the setup change | J4: XWALK_NO_FILE_CONFIG | K4: Not Run
A5: CFG-04 | B5: Setup and configuration | C5: Period row with code and SQL | D5: Set both Rpt_Period_Cd and Rpt_Dt_Sql_Txt on one ComplianceRunTypePeriod row | F5: UPDATE HSABC_DEV.ComplianceRunTypePeriod SET Rpt_Dt_Sql_Txt = 'SELECT CURRENT_DATE AS rpt_start, CURRENT_DATE AS rpt_end' WHERE Project_Cd = 'CMSUNIV' AND Table_Nm = '*' AND Run_Ty = 'DLY'; -- revert after: SET Rpt_Dt_Sql_Txt = NULL | G5: Worker shell (TERADATA_* and FRAMEWORK_METADATA_SCHEMA=HSABC_DEV set): python -m compliance_framework.cli validate-config | H5: 1. Check the precondition and run the setup SQL 2. Prepare the input: Set both Rpt_Period_Cd and Rpt_Dt_Sql_Txt on one ComplianceRunTypePeriod row 3. Run the job 4. Check the task log / step report 5. Compare with the expected result and record the outcome 6. Revert the setup change | J5: RUN_TYPE_PERIOD: "not both (the code is used)" | K5: Not Run
A6: CFG-05 | B6: Setup and configuration | C6: Bad period code | D6: Rpt_Period_Cd = 'PREV_DAYS' | F6: UPDATE HSABC_DEV.ComplianceRunTypePeriod SET Rpt_Period_Cd = 'PREV_DAYS' WHERE Project_Cd = 'CMSUNIV' AND Table_Nm = '*' AND Run_Ty = 'DLY'; -- revert after: SET Rpt_Period_Cd = 'PREV_DAY' | G6: Worker shell (TERADATA_* and FRAMEWORK_METADATA_SCHEMA=HSABC_DEV set): python -m compliance_framework.cli validate-config | H6: 1. Check the precondition and run the setup SQL 2. Prepare the input: Rpt_Period_Cd = 'PREV_DAYS' 3. Run the job 4. Check the task log / step report 5. Compare with the expected result and record the outcome 6. Revert the setup change | J6: RPT_PERIOD error | K6: Not Run
A7: CFG-06 | B7: Setup and configuration | C7: Crosswalk row with code and SQL | D7: Both on one crosswalk row | F7: UPDATE HSABC_DEV.ComplianceDataSetSourceXwalk SET Rpt_Period_Cd = 'PREV_DAY', Rpt_Dt_Sql_Txt = 'SELECT 1' WHERE Project_Cd = 'CMSUNIV' AND Table_Nm = 'ODAG3' AND Src_ID = '51'; -- revert after: SET both = NULL | G7: Worker shell (TERADATA_* and FRAMEWORK_METADATA_SCHEMA=HSABC_DEV set): python -m compliance_framework.cli validate-config | H7: 1. Check the precondition and run the setup SQL 2. Prepare the input: Both on one crosswalk row 3. Run the job 4. Check the task log / step report 5. Compare with the expected result and record the outcome 6. Revert the setup change | J7: RPT_PERIOD "not both" | K7: Not Run
A8: CFG-07 | B8: Setup and configuration | C8: Export statement checks | D8: Exp_Pre_Sql_Txt with {batch}; Exp_Post_Sql_Txt with two statements; Exp_Sql_Txt an UPDATE | F8: UPDATE HSABC_DEV.ComplianceExportConfig SET Exp_Pre_Sql_Txt = 'DELETE FROM x WHERE y = {batch}', Exp_Post_Sql_Txt = 'DELETE FROM x; DELETE FROM y', Exp_Sql_Txt = 'UPDATE x SET y = 1' WHERE Project_Cd = 'CMSUNIV' AND Table_Nm = 'ODAG3'; -- revert after: SET all three = NULL | G8: Worker shell (TERADATA_* and FRAMEWORK_METADATA_SCHEMA=HSABC_DEV set): python -m compliance_framework.cli validate-config | H8: 1. Check the precondition and run the setup SQL 2. Prepare the input: Exp_Pre_Sql_Txt with {batch}; Exp_Post_Sql_Txt with two statements; Exp_Sql_Txt an UPDATE 3. Run the job 4. Check the task log / step report 5. Compare with the expected result and record the outcome 6. Revert the setup change | J8: EXPORT_CONFIG errors: unknown placeholder, "one statement", "must be a SELECT" | K8: Not Run
A9: CFG-08 | B9: Setup and configuration | C9: Staging ↔ core pairing shown | D9: Validate with SNPCC1 (staging Member…, core Enrollee…) | G9: Worker shell (TERADATA_* and FRAMEWORK_METADATA_SCHEMA=HSABC_DEV set): python -m compliance_framework.cli validate-config | H9: 1. Check the precondition 2. Prepare the input: Validate with SNPCC1 (staging Member…, core Enrollee…) 3. Run the job 4. Check the task log / step report 5. Compare with the expected result and record the outcome | J9: Log line staging -> core by column position: memberfirstname -> enrolleefirstname, … | K9: Not Run
A10: CFG-09 | B10: Setup and configuration | C10: Template overlap | D10: Two file configs whose templates match the same name | G10: Worker shell (TERADATA_* and FRAMEWORK_METADATA_SCHEMA=HSABC_DEV set): python -m compliance_framework.cli validate-config | H10: 1. Check the precondition 2. Prepare the input: Two file configs whose templates match the same name 3. Run the job 4. Check the task log / step report 5. Compare with the expected result and record the outcome | J10: TEMPLATE_OVERLAP | K10: Not Run
A11: CFG-10 | B11: Setup and configuration | C11: Test connections | D11: test-connection | G11: Worker shell (TERADATA_* and FRAMEWORK_METADATA_SCHEMA=HSABC_DEV set): python -m compliance_framework.cli test-connection | H11: 1. Check the precondition 2. Prepare the input: test-connection 3. Run the job 4. Check the task log / step report 5. Compare with the expected result and record the outcome | J11: Teradata and NAS OK; failures show the reason, no password | K11: Not Run
A12: CFG-11 | B12: Setup and configuration | C12: Missing framework table | D12: Rename ComplianceFileLoad (DEV only), run FILE_LOAD, rename back | F12: RENAME TABLE HSABC_DEV.ComplianceFileLoad TO HSABC_DEV.ComplianceFileLoad_x; -- DEV only -- revert after: RENAME TABLE HSABC_DEV.ComplianceFileLoad_x TO HSABC_DEV.ComplianceFileLoad; | G12: Airflow DAG OSSTD_CORE_CMS_COMPLIANCE_FILE_LOAD Trigger DAG w/ config: {"project": "CMSUNIV"} | H12: 1. Check the precondition and run the setup SQL 2. Prepare the input: Rename ComplianceFileLoad (DEV only), run FILE_LOAD, rename back 3. Run the job 4. Run the verification SQL (replace <batch>, <table>) 5. Compare with the expected result and record the outcome 6. Revert the setup change | I12: SELECT TableName FROM DBC.TablesV WHERE DatabaseName = 'HSABC_DEV' AND (TableName LIKE 'Compliance%' OR TableName = 'CMS_ComplianceExceptionsAudit') ORDER BY 1; | J12: Load PROCESS_FAILURE / step "COULD NOT RUN" with error 3807; retried; nothing half done | K12: Not Run
A13: CFG-12 | B13: Setup and configuration | C13: Variables minimal | D13: Open each Variable | G13: Airflow Admin -> Variables (review only) | H13: 1. Check the precondition 2. Prepare the input: Open each Variable 3. Run the job 4. Check the task log / step report 5. Compare with the expected result and record the outcome | J13: Only td_conn_var, meta_db, load_env, email_recipient, project (+ trigger_dags, FILE_CHECK settings, FILE_RULES pool, EXPORT_LOAD wait_for_triggered) | K13: Not Run
A14: BC-01 | B14: Batch creation | C14: Daily batches | D14: Any day | E14: Trigger BATCH_CREATION ({"project": "CMSUNIV"} unless stated). Check with Q1 / Q2. | G14: Airflow DAG OSSTD_CORE_CMS_COMPLIANCE_BATCH_CREATION Trigger DAG w/ config: {"project": "CMSUNIV"} | H14: 1. Check the precondition 2. Prepare the input: Any day 3. Run the job 4. Run the verification SQL (replace <batch>, <table>) 5. Compare with the expected result and record the outcome | I14: SELECT Btch_ID, Src_ID, Run_Ty, Rpt_Start_Dt_Key, Rpt_End_Dt_Key, Req_Dt_Key, Req_Stat, Resolution_Ty, Batch_Close_Ind, Cmplnc_Vrsn FROM HSABC_DEV.ComplianceRequestControl WHERE Project_Cd = 'CMSUNIV' AND Req_Dt_Key = CURRENT_DATE ORDER BY Btch_ID, Src_ID; | J14: One …_<table>_DLY batch per table, one row per crosswalk source listing DLY; report dates = previous day; REQUEST_CREATED; close date = request date (SLA 1); version 2200 | K14: Not Run
A15: BC-02 | B15: Batch creation | C15: Batch ID format | D15: BC-01 | E15: Trigger BATCH_CREATION ({"project": "CMSUNIV"} unless stated). Check with Q1 / Q2. | G15: Airflow DAG OSSTD_CORE_CMS_COMPLIANCE_BATCH_CREATION Trigger DAG w/ config: {"project": "CMSUNIV"} | H15: 1. Check the precondition 2. Prepare the input: BC-01 3. Run the job 4. Run the verification SQL (replace <batch>, <table>) 5. Compare with the expected result and record the outcome | I15: SELECT Btch_ID, Src_ID, Run_Ty, Rpt_Start_Dt_Key, Rpt_End_Dt_Key, Req_Dt_Key, Req_Stat, Resolution_Ty, Batch_Close_Ind, Cmplnc_Vrsn FROM HSABC_DEV.ComplianceRequestControl WHERE Project_Cd = 'CMSUNIV' AND Req_Dt_Key = CURRENT_DATE ORDER BY Btch_ID, Src_ID; | J15: Btch_ID = <YYYYMMDD>_CMSUNIV_<table>_<run type>; all sources share it | K15: Not Run
A16: BC-03 | B16: Batch creation | C16: Rerun is safe | D16: Trigger BC-01 again | E16: Trigger BATCH_CREATION ({"project": "CMSUNIV"} unless stated). Check with Q1 / Q2. | G16: Airflow DAG OSSTD_CORE_CMS_COMPLIANCE_BATCH_CREATION Trigger DAG w/ config: {"project": "CMSUNIV"} | H16: 1. Check the precondition 2. Prepare the input: Trigger BC-01 again 3. Run the job 4. Run the verification SQL (replace <batch>, <table>) 5. Compare with the expected result and record the outcome | I16: SELECT Btch_ID, Src_ID, Run_Ty, Rpt_Start_Dt_Key, Rpt_End_Dt_Key, Req_Dt_Key, Req_Stat, Resolution_Ty, Batch_Close_Ind, Cmplnc_Vrsn FROM HSABC_DEV.ComplianceRequestControl WHERE Project_Cd = 'CMSUNIV' AND Req_Dt_Key = CURRENT_DATE ORDER BY Btch_ID, Src_ID; | J16: No new rows (Q1 unchanged); report created = 0 | K16: Not Run
A17: BC-04 | B17: Batch creation | C17: Weekly on Sunday | D17: Run the job with the trigger config shown in Job to Execute | E17: Trigger BATCH_CREATION ({"project": "CMSUNIV"} unless stated). Check with Q1 / Q2. | G17: Airflow DAG OSSTD_CORE_CMS_COMPLIANCE_BATCH_CREATION Trigger DAG w/ config: {"project": "CMSUNIV", "as_of": "2026-10-25"} | H17: 1. Check the precondition 2. No input to prepare 3. Run the job 4. Run the verification SQL (replace <batch>, <table>) 5. Compare with the expected result and record the outcome | I17: SELECT Btch_ID, Src_ID, Run_Ty, Rpt_Start_Dt_Key, Rpt_End_Dt_Key, Req_Dt_Key, Req_Stat, Resolution_Ty, Batch_Close_Ind, Cmplnc_Vrsn FROM HSABC_DEV.ComplianceRequestControl WHERE Project_Cd = 'CMSUNIV' AND Req_Dt_Key = CURRENT_DATE ORDER BY Btch_ID, Src_ID; | J17: …_WKLY batches for internal-source tables only; dates = the 60 days ending the Saturday before; SLA 5 (closes Friday) | K17: Not Run
A18: BC-05 | B18: Batch creation | C18: No weekly on other days | D18: as_of a Monday | E18: Trigger BATCH_CREATION ({"project": "CMSUNIV"} unless stated). Check with Q1 / Q2. | G18: Airflow DAG OSSTD_CORE_CMS_COMPLIANCE_BATCH_CREATION Trigger DAG w/ config: {"project": "CMSUNIV", "as_of": "2026-10-26"} | H18: 1. Check the precondition 2. Prepare the input: as_of a Monday 3. Run the job 4. Run the verification SQL (replace <batch>, <table>) 5. Compare with the expected result and record the outcome | I18: SELECT Btch_ID, Src_ID, Run_Ty, Rpt_Start_Dt_Key, Rpt_End_Dt_Key, Req_Dt_Key, Req_Stat, Resolution_Ty, Batch_Close_Ind, Cmplnc_Vrsn FROM HSABC_DEV.ComplianceRequestControl WHERE Project_Cd = 'CMSUNIV' AND Req_Dt_Key = CURRENT_DATE ORDER BY Btch_ID, Src_ID; | J18: No WKLY batches | K18: Not Run
A19: BC-06 | B19: Batch creation | C19: Monthly (MNT) | D19: as_of = the Sunday before the 3rd Tuesday (e.g. 2026-10-18) | E19: Trigger BATCH_CREATION ({"project": "CMSUNIV"} unless stated). Check with Q1 / Q2. | G19: Airflow DAG OSSTD_CORE_CMS_COMPLIANCE_BATCH_CREATION Trigger DAG w/ config: {"project": "CMSUNIV", "as_of": "2026-10-18"} | H19: 1. Check the precondition 2. Prepare the input: as_of = the Sunday before the 3rd Tuesday (e.g. 2026-10-18) 3. Run the job 4. Run the verification SQL (replace <batch>, <table>) 5. Compare with the expected result and record the outcome | I19: SELECT Btch_ID, Src_ID, Run_Ty, Rpt_Start_Dt_Key, Rpt_End_Dt_Key, Req_Dt_Key, Req_Stat, Resolution_Ty, Batch_Close_Ind, Cmplnc_Vrsn FROM HSABC_DEV.ComplianceRequestControl WHERE Project_Cd = 'CMSUNIV' AND Req_Dt_Key = CURRENT_DATE ORDER BY Btch_ID, Src_ID; | J19: …_MNT batches, dates = previous calendar month (2026-09-01..09-30), SLA 5 | K19: Not Run
A20: BC-07 | B20: Batch creation | C20: MNT not on other Sundays | D20: as_of another Sunday | E20: Trigger BATCH_CREATION ({"project": "CMSUNIV"} unless stated). Check with Q1 / Q2. | G20: Airflow DAG OSSTD_CORE_CMS_COMPLIANCE_BATCH_CREATION Trigger DAG w/ config: {"project": "CMSUNIV", "as_of": "2026-10-25"} | H20: 1. Check the precondition 2. Prepare the input: as_of another Sunday 3. Run the job 4. Run the verification SQL (replace <batch>, <table>) 5. Compare with the expected result and record the outcome | I20: SELECT Btch_ID, Src_ID, Run_Ty, Rpt_Start_Dt_Key, Rpt_End_Dt_Key, Req_Dt_Key, Req_Stat, Resolution_Ty, Batch_Close_Ind, Cmplnc_Vrsn FROM HSABC_DEV.ComplianceRequestControl WHERE Project_Cd = 'CMSUNIV' AND Req_Dt_Key = CURRENT_DATE ORDER BY Btch_ID, Src_ID; | J20: No MNT batches | K20: Not Run
A21: BC-08 | B21: Batch creation | C21: Missed day caught up | D21: Skip a day; run next day with lookback_days: 2 | E21: Trigger BATCH_CREATION ({"project": "CMSUNIV"} unless stated). Check with Q1 / Q2. | G21: Airflow DAG OSSTD_CORE_CMS_COMPLIANCE_BATCH_CREATION Trigger DAG w/ config: {"project": "CMSUNIV", "lookback_days": "2"} | H21: 1. Check the precondition 2. Prepare the input: Skip a day; run next day with lookback_days: 2 3. Run the job 4. Run the verification SQL (replace <batch>, <table>) 5. Compare with the expected result and record the outcome | I21: SELECT Btch_ID, Src_ID, Run_Ty, Rpt_Start_Dt_Key, Rpt_End_Dt_Key, Req_Dt_Key, Req_Stat, Resolution_Ty, Batch_Close_Ind, Cmplnc_Vrsn FROM HSABC_DEV.ComplianceRequestControl WHERE Project_Cd = 'CMSUNIV' AND Req_Dt_Key = CURRENT_DATE ORDER BY Btch_ID, Src_ID; | J21: Missed day's DLY batches created with that day's dates (Req_Dt_Key = missed day) | K21: Not Run
A22: BC-09 | B22: Batch creation | C22: Period override | D22: Run the job with the trigger config shown in Job to Execute | E22: Trigger BATCH_CREATION ({"project": "CMSUNIV"} unless stated). Check with Q1 / Q2. | G22: Airflow DAG OSSTD_CORE_CMS_COMPLIANCE_BATCH_CREATION Trigger DAG w/ config: {"project": "CMSUNIV", "run_type": "DLY", "period": "PREV_N_DAYS(3)"} | H22: 1. Check the precondition 2. No input to prepare 3. Run the job 4. Run the verification SQL (replace <batch>, <table>) 5. Compare with the expected result and record the outcome | I22: SELECT Btch_ID, Src_ID, Run_Ty, Rpt_Start_Dt_Key, Rpt_End_Dt_Key, Req_Dt_Key, Req_Stat, Resolution_Ty, Batch_Close_Ind, Cmplnc_Vrsn FROM HSABC_DEV.ComplianceRequestControl WHERE Project_Cd = 'CMSUNIV' AND Req_Dt_Key = CURRENT_DATE ORDER BY Btch_ID, Src_ID; | J22: DLY batches with the last 3 days as dates | K22: Not Run
A23: BC-10 | B23: Batch creation | C23: Scope | D23: Run the job with the trigger config shown in Job to Execute | E23: Trigger BATCH_CREATION ({"project": "CMSUNIV"} unless stated). Check with Q1 / Q2. | G23: Airflow DAG OSSTD_CORE_CMS_COMPLIANCE_BATCH_CREATION Trigger DAG w/ config: {"project": "CMSUNIV", "table_group": "SNPCC"} | H23: 1. Check the precondition 2. No input to prepare 3. Run the job 4. Run the verification SQL (replace <batch>, <table>) 5. Compare with the expected result and record the outcome | I23: SELECT Btch_ID, Src_ID, Run_Ty, Rpt_Start_Dt_Key, Rpt_End_Dt_Key, Req_Dt_Key, Req_Stat, Resolution_Ty, Batch_Close_Ind, Cmplnc_Vrsn FROM HSABC_DEV.ComplianceRequestControl WHERE Project_Cd = 'CMSUNIV' AND Req_Dt_Key = CURRENT_DATE ORDER BY Btch_ID, Src_ID; | J23: Only SNPCC1 batches | K23: Not Run
A24: BC-11 | B24: Batch creation | C24: FA fixed dates | D24: Run DLY | E24: Trigger BATCH_CREATION ({"project": "CMSUNIV"} unless stated). Check with Q1 / Q2. | G24: Airflow DAG OSSTD_CORE_CMS_COMPLIANCE_BATCH_CREATION Trigger DAG w/ config: {"project": "CMSUNIV"} | H24: 1. Check the precondition 2. Prepare the input: Run DLY 3. Run the job 4. Run the verification SQL (replace <batch>, <table>) 5. Compare with the expected result and record the outcome | I24: SELECT Btch_ID, Src_ID, Run_Ty, Rpt_Start_Dt_Key, Rpt_End_Dt_Key, Req_Dt_Key, Req_Stat, Resolution_Ty, Batch_Close_Ind, Cmplnc_Vrsn FROM HSABC_DEV.ComplianceRequestControl WHERE Project_Cd = 'CMSUNIV' AND Req_Dt_Key = CURRENT_DATE ORDER BY Btch_ID, Src_ID; | J24: FA1 = last 14 days of previous month; FA2 = 01-01..01-31; FA3 = 11-01..12-31 previous year; FA4 = 11-01 previous year..01-31 | K24: Not Run
A25: BC-12 | B25: Batch creation | C25: FA switch on Feb 1 | D25: as_of 2027-01-31 then 2027-02-01 | E25: Trigger BATCH_CREATION ({"project": "CMSUNIV"} unless stated). Check with Q1 / Q2. | G25: Airflow DAG OSSTD_CORE_CMS_COMPLIANCE_BATCH_CREATION Trigger DAG w/ config: {"project": "CMSUNIV", "as_of": "2027-01-31"} then again with as_of 2027-02-01 | H25: 1. Check the precondition 2. Prepare the input: as_of 2027-01-31 then 2027-02-01 3. Run the job 4. Run the verification SQL (replace <batch>, <table>) 5. Compare with the expected result and record the outcome | I25: SELECT Btch_ID, Src_ID, Run_Ty, Rpt_Start_Dt_Key, Rpt_End_Dt_Key, Req_Dt_Key, Req_Stat, Resolution_Ty, Batch_Close_Ind, Cmplnc_Vrsn FROM HSABC_DEV.ComplianceRequestControl WHERE Project_Cd = 'CMSUNIV' AND Req_Dt_Key = CURRENT_DATE ORDER BY Btch_ID, Src_ID; | J25: FA2–FA4 dates move to the new year on 02-01 only | K25: Not Run
A26: BC-13 | B26: Batch creation | C26: IN1 ad hoc with schedule | D26: Any day | E26: Trigger BATCH_CREATION ({"project": "CMSUNIV"} unless stated). Check with Q1 / Q2. | G26: Airflow DAG OSSTD_CORE_CMS_COMPLIANCE_BATCH_CREATION Trigger DAG w/ config: {"project": "CMSUNIV"} | H26: 1. Check the precondition 2. Prepare the input: Any day 3. Run the job 4. Run the verification SQL (replace <batch>, <table>) 5. Compare with the expected result and record the outcome | I26: SELECT Btch_ID, Src_ID, Run_Ty, Rpt_Start_Dt_Key, Rpt_End_Dt_Key, Req_Dt_Key, Req_Stat, Resolution_Ty, Batch_Close_Ind, Cmplnc_Vrsn FROM HSABC_DEV.ComplianceRequestControl WHERE Project_Cd = 'CMSUNIV' AND Req_Dt_Key = CURRENT_DATE ORDER BY Btch_ID, Src_ID; | J26: …_SNPCC1_IN1 batch for source 11 only; held (not pulled / exported) | K26: Not Run
A27: BC-14 | B27: Batch creation | C27: Crosswalk effective dates | D27: Set a source's Effective_End_Dt_Key to yesterday | E27: Trigger BATCH_CREATION ({"project": "CMSUNIV"} unless stated). Check with Q1 / Q2. | F27: UPDATE HSABC_DEV.ComplianceDataSetSourceXwalk SET Effective_End_Dt_Key = CURRENT_DATE - 1 WHERE Project_Cd = 'CMSUNIV' AND Table_Nm = 'ODAG3' AND Src_ID = '51'; -- revert after: SET Effective_End_Dt_Key = NULL | G27: Airflow DAG OSSTD_CORE_CMS_COMPLIANCE_BATCH_CREATION Trigger DAG w/ config: {"project": "CMSUNIV"} | H27: 1. Check the precondition and run the setup SQL 2. Prepare the input: Set a source's Effective_End_Dt_Key to yesterday 3. Run the job 4. Run the verification SQL (replace <batch>, <table>) 5. Compare with the expected result and record the outcome 6. Revert the setup change | I27: SELECT Btch_ID, Src_ID, Run_Ty, Rpt_Start_Dt_Key, Rpt_End_Dt_Key, Req_Dt_Key, Req_Stat, Resolution_Ty, Batch_Close_Ind, Cmplnc_Vrsn FROM HSABC_DEV.ComplianceRequestControl WHERE Project_Cd = 'CMSUNIV' AND Req_Dt_Key = CURRENT_DATE ORDER BY Btch_ID, Src_ID; | J27: No new batch row for that source from today | K27: Not Run
A28: BC-15 | B28: Batch creation | C28: Run type switched off for a source | D28: Add a crosswalk row Include_Ind = 0 for one run type from today | E28: Trigger BATCH_CREATION ({"project": "CMSUNIV"} unless stated). Check with Q1 / Q2. | F28: INSERT INTO HSABC_DEV.ComplianceDataSetSourceXwalk (Project_Cd, Table_Nm, Src_ID, Run_Ty, Effective_Start_Dt_Key, Effective_End_Dt_Key, Cmplnc_Vrsn, Include_Ind, Active_Ind) VALUES ('CMSUNIV', 'ODAG3', '51', 'MNT', CURRENT_DATE, NULL, '2200', 0, 1); -- revert after: DELETE that row | G28: Airflow DAG OSSTD_CORE_CMS_COMPLIANCE_BATCH_CREATION Trigger DAG w/ config: {"project": "CMSUNIV"} | H28: 1. Check the precondition and run the setup SQL 2. Prepare the input: Add a crosswalk row Include_Ind = 0 for one run type from today 3. Run the job 4. Run the verification SQL (replace <batch>, <table>) 5. Compare with the expected result and record the outcome 6. Revert the setup change | I28: SELECT Btch_ID, Src_ID, Run_Ty, Rpt_Start_Dt_Key, Rpt_End_Dt_Key, Req_Dt_Key, Req_Stat, Resolution_Ty, Batch_Close_Ind, Cmplnc_Vrsn FROM HSABC_DEV.ComplianceRequestControl WHERE Project_Cd = 'CMSUNIV' AND Req_Dt_Key = CURRENT_DATE ORDER BY Btch_ID, Src_ID; | J28: That source gets no batch of that run type from today; earlier batches untouched | K28: Not Run
A29: BC-16 | B29: Batch creation | C29: Inactive run type | D29: Active_Ind = 0 on a run type | E29: Trigger BATCH_CREATION ({"project": "CMSUNIV"} unless stated). Check with Q1 / Q2. | F29: UPDATE HSABC_DEV.ComplianceRunType SET Active_Ind = 0 WHERE Run_Ty = 'IN1'; -- revert after: SET Active_Ind = 1 | G29: Airflow DAG OSSTD_CORE_CMS_COMPLIANCE_BATCH_CREATION Trigger DAG w/ config: {"project": "CMSUNIV"} | H29: 1. Check the precondition and run the setup SQL 2. Prepare the input: Active_Ind = 0 on a run type 3. Run the job 4. Run the verification SQL (replace <batch>, <table>) 5. Compare with the expected result and record the outcome 6. Revert the setup change | I29: SELECT Btch_ID, Src_ID, Run_Ty, Rpt_Start_Dt_Key, Rpt_End_Dt_Key, Req_Dt_Key, Req_Stat, Resolution_Ty, Batch_Close_Ind, Cmplnc_Vrsn FROM HSABC_DEV.ComplianceRequestControl WHERE Project_Cd = 'CMSUNIV' AND Req_Dt_Key = CURRENT_DATE ORDER BY Btch_ID, Src_ID; | J29: No batches of it; validate WARNING | K29: Not Run
A30: BC-17 | B30: Batch creation | C30: Report dates by SQL | D30: Period row with Rpt_Dt_Sql_Txt (e.g. 14 days before {period_dt}) | E30: Trigger BATCH_CREATION ({"project": "CMSUNIV"} unless stated). Check with Q1 / Q2. | F30: INSERT INTO HSABC_DEV.ComplianceRunTypePeriod (Project_Cd, Table_Nm, Run_Ty, Rpt_Dt_Sql_Txt, Active_Ind) VALUES ('CMSUNIV', 'ODAG3', 'DLY', 'SELECT CAST({period_dt} AS DATE) - 14 AS rpt_start, CAST({period_dt} AS DATE) - 1 AS rpt_end', 1); -- revert after: DELETE that row | G30: Airflow DAG OSSTD_CORE_CMS_COMPLIANCE_BATCH_CREATION Trigger DAG w/ config: {"project": "CMSUNIV"} | H30: 1. Check the precondition and run the setup SQL 2. Prepare the input: Period row with Rpt_Dt_Sql_Txt (e.g. 14 days before {period_dt}) 3. Run the job 4. Run the verification SQL (replace <batch>, <table>) 5. Compare with the expected result and record the outcome 6. Revert the setup change | I30: SELECT Btch_ID, Src_ID, Run_Ty, Rpt_Start_Dt_Key, Rpt_End_Dt_Key, Req_Dt_Key, Req_Stat, Resolution_Ty, Batch_Close_Ind, Cmplnc_Vrsn FROM HSABC_DEV.ComplianceRequestControl WHERE Project_Cd = 'CMSUNIV' AND Req_Dt_Key = CURRENT_DATE ORDER BY Btch_ID, Src_ID; | J30: Batch dates from the SQL; SQL with values in the log | K30: Not Run
A31: BC-18 | B31: Batch creation | C31: SQL returns no row | D31: Make that SQL return nothing | E31: Trigger BATCH_CREATION ({"project": "CMSUNIV"} unless stated). Check with Q1 / Q2. | F31: UPDATE HSABC_DEV.ComplianceRunTypePeriod SET Rpt_Dt_Sql_Txt = 'SELECT CURRENT_DATE AS rpt_start, CURRENT_DATE AS rpt_end WHERE 1 = 0' WHERE Project_Cd = 'CMSUNIV' AND Table_Nm = 'ODAG3' AND Run_Ty = 'DLY'; | G31: Airflow DAG OSSTD_CORE_CMS_COMPLIANCE_BATCH_CREATION Trigger DAG w/ config: {"project": "CMSUNIV"} | H31: 1. Check the precondition and run the setup SQL 2. Prepare the input: Make that SQL return nothing 3. Run the job 4. Run the verification SQL (replace <batch>, <table>) 5. Compare with the expected result and record the outcome | I31: SELECT Btch_ID, Src_ID, Run_Ty, Rpt_Start_Dt_Key, Rpt_End_Dt_Key, Req_Dt_Key, Req_Stat, Resolution_Ty, Batch_Close_Ind, Cmplnc_Vrsn FROM HSABC_DEV.ComplianceRequestControl WHERE Project_Cd = 'CMSUNIV' AND Req_Dt_Key = CURRENT_DATE ORDER BY Btch_ID, Src_ID; | J31: No batch that day for that table; no error | K31: Not Run
A32: BC-19 | B32: Batch creation | C32: Calendar batch | D32: Insert a ComplianceBatchCalendar row for today | E32: Trigger BATCH_CREATION ({"project": "CMSUNIV"} unless stated). Check with Q1 / Q2. | F32: INSERT INTO HSABC_DEV.ComplianceBatchCalendar (Project_Cd, Table_Nm, Run_Ty, Req_Dt_Key, Rpt_Start_Dt_Key, Rpt_End_Dt_Key, Active_Ind) VALUES ('CMSUNIV', 'ODAG3', 'MNT', CURRENT_DATE, DATE '2026-09-01', DATE '2026-09-30', 1); | G32: Airflow DAG OSSTD_CORE_CMS_COMPLIANCE_BATCH_CREATION Trigger DAG w/ config: {"project": "CMSUNIV"} | H32: 1. Check the precondition and run the setup SQL 2. Prepare the input: Insert a ComplianceBatchCalendar row for today 3. Run the job 4. Run the verification SQL (replace <batch>, <table>) 5. Compare with the expected result and record the outcome | I32: SELECT Btch_ID, Src_ID, Run_Ty, Rpt_Start_Dt_Key, Rpt_End_Dt_Key, Req_Dt_Key, Req_Stat, Resolution_Ty, Batch_Close_Ind, Cmplnc_Vrsn FROM HSABC_DEV.ComplianceRequestControl WHERE Project_Cd = 'CMSUNIV' AND Req_Dt_Key = CURRENT_DATE ORDER BY Btch_ID, Src_ID; | J32: Batch with the calendar dates | K32: Not Run
A33: BC-20 | B33: Batch creation | C33: Version per source | D33: Crosswalk row of one source with version 2300 | E33: Trigger BATCH_CREATION ({"project": "CMSUNIV"} unless stated). Check with Q1 / Q2. | F33: UPDATE HSABC_DEV.ComplianceDataSetSourceXwalk SET Cmplnc_Vrsn = '2300' WHERE Project_Cd = 'CMSUNIV' AND Table_Nm = 'ODAG3' AND Src_ID = '51'; -- revert after: SET Cmplnc_Vrsn = '2200' | G33: Airflow DAG OSSTD_CORE_CMS_COMPLIANCE_BATCH_CREATION Trigger DAG w/ config: {"project": "CMSUNIV"} | H33: 1. Check the precondition and run the setup SQL 2. Prepare the input: Crosswalk row of one source with version 2300 3. Run the job 4. Run the verification SQL (replace <batch>, <table>) 5. Compare with the expected result and record the outcome 6. Revert the setup change | I33: SELECT Btch_ID, Src_ID, Run_Ty, Rpt_Start_Dt_Key, Rpt_End_Dt_Key, Req_Dt_Key, Req_Stat, Resolution_Ty, Batch_Close_Ind, Cmplnc_Vrsn FROM HSABC_DEV.ComplianceRequestControl WHERE Project_Cd = 'CMSUNIV' AND Req_Dt_Key = CURRENT_DATE ORDER BY Btch_ID, Src_ID; | J33: That source's row has Cmplnc_Vrsn = 2300 | K33: Not Run
A34: BC-21 | B34: Batch creation | C34: Problems reported | D34: Break a period code; run | E34: Trigger BATCH_CREATION ({"project": "CMSUNIV"} unless stated). Check with Q1 / Q2. | F34: UPDATE HSABC_DEV.ComplianceRunTypePeriod SET Rpt_Period_Cd = 'PREV_DAYS' WHERE Project_Cd = 'CMSUNIV' AND Table_Nm = 'ODAG3' AND Run_Ty = 'DLY'; -- revert after | G34: Airflow DAG OSSTD_CORE_CMS_COMPLIANCE_BATCH_CREATION Trigger DAG w/ config: {"project": "CMSUNIV"} | H34: 1. Check the precondition and run the setup SQL 2. Prepare the input: Break a period code; run 3. Run the job 4. Run the verification SQL (replace <batch>, <table>) 5. Compare with the expected result and record the outcome 6. Revert the setup change | I34: SELECT Btch_ID, Src_ID, Run_Ty, Rpt_Start_Dt_Key, Rpt_End_Dt_Key, Req_Dt_Key, Req_Stat, Resolution_Ty, Batch_Close_Ind, Cmplnc_Vrsn FROM HSABC_DEV.ComplianceRequestControl WHERE Project_Cd = 'CMSUNIV' AND Req_Dt_Key = CURRENT_DATE ORDER BY Btch_ID, Src_ID; | J34: Other batches still created; task fails (exit 1) with the error in the report; failure email | K34: Not Run
A35: IN-01 | B35: Ad-hoc requests | C35: One-day request | D35: Above | E35: Insert into ComplianceRequestInTake, then run BATCH_CREATION. INSERT INTO HSABC_DEV.ComplianceRequestInTake (Project_Cd, Table_Nm, Src_ID, Run_Ty, Cmplnc_Vrsn, Rpt_Start_Dt_Key, Rpt_End_Dt_Key, Req_Start_Dt_Key, Req_End_Dt_Key) VALUES ('CMSUNIV', 'ODAG3', '51', 'CMS', '2200', DATE '2026-09-01', DATE '2026-09-30', CURRENT_DATE, CURRENT_DATE); | F35: INSERT INTO HSABC_DEV.ComplianceRequestInTake (Project_Cd, Table_Nm, Src_ID, Run_Ty, Cmplnc_Vrsn, Rpt_Start_Dt_Key, Rpt_End_Dt_Key, Req_Start_Dt_Key, Req_End_Dt_Key) VALUES ('CMSUNIV', 'ODAG3', '51', 'CMS', '2200', DATE '2026-09-01', DATE '2026-09-30', CURRENT_DATE, CURRENT_DATE); | G35: Airflow DAG OSSTD_CORE_CMS_COMPLIANCE_BATCH_CREATION Trigger DAG w/ config: {"project": "CMSUNIV"} | H35: 1. Check the precondition and run the setup SQL 2. Prepare the input: Above 3. Run the job 4. Run the verification SQL (replace <batch>, <table>) 5. Compare with the expected result and record the outcome | I35: SELECT Intake_ID, Table_Nm, Src_ID, Run_Ty, Req_Start_Dt_Key, Req_End_Dt_Key, Last_Run_Dt_Key FROM HSABC_DEV.ComplianceRequestInTake ORDER BY Intake_ID DESC; SELECT Btch_ID, Src_ID, Run_Ty, Rpt_Start_Dt_Key, Rpt_End_Dt_Key, Req_Dt_Key, Req_Stat, Resolution_Ty, Batch_Close_Ind, Cmplnc_Vrsn FROM HSABC_DEV.ComplianceRequestControl WHERE Project_Cd = 'CMSUNIV' AND Req_Dt_Key = CURRENT_DATE ORDER BY Btch_ID, Src_ID; | J35: One …_ODAG3_CMS batch, source 51, the request's dates, SLA 1 | K35: Not Run
A36: IN-02 | B36: Ad-hoc requests | C36: Multi-day request | D36: Req_End_Dt_Key = CURRENT_DATE + 2; run 3 days (as_of) | E36: Insert into ComplianceRequestInTake, then run BATCH_CREATION. INSERT INTO HSABC_DEV.ComplianceRequestInTake (Project_Cd, Table_Nm, Src_ID, Run_Ty, Cmplnc_Vrsn, Rpt_Start_Dt_Key, Rpt_End_Dt_Key, Req_Start_Dt_Key, Req_End_Dt_Key) VALUES ('CMSUNIV', 'ODAG3', '51', 'CMS', '2200', DATE '2026-09-01', DATE '2026-09-30', CURRENT_DATE, CURRENT_DATE); | F36: INSERT INTO HSABC_DEV.ComplianceRequestInTake (Project_Cd, Table_Nm, Src_ID, Run_Ty, Cmplnc_Vrsn, Rpt_Start_Dt_Key, Rpt_End_Dt_Key, Req_Start_Dt_Key, Req_End_Dt_Key) VALUES ('CMSUNIV', 'ODAG3', '51', 'CMS', '2200', DATE '2026-09-01', DATE '2026-09-30', CURRENT_DATE, CURRENT_DATE + 2); | G36: Airflow DAG OSSTD_CORE_CMS_COMPLIANCE_BATCH_CREATION Trigger DAG w/ config: {"project": "CMSUNIV"} | H36: 1. Check the precondition and run the setup SQL 2. Prepare the input: Req_End_Dt_Key = CURRENT_DATE + 2; run 3 days (as_of) 3. Run the job 4. Run the verification SQL (replace <batch>, <table>) 5. Compare with the expected result and record the outcome | I36: SELECT Intake_ID, Table_Nm, Src_ID, Run_Ty, Req_Start_Dt_Key, Req_End_Dt_Key, Last_Run_Dt_Key FROM HSABC_DEV.ComplianceRequestInTake ORDER BY Intake_ID DESC; SELECT Btch_ID, Src_ID, Run_Ty, Rpt_Start_Dt_Key, Rpt_End_Dt_Key, Req_Dt_Key, Req_Stat, Resolution_Ty, Batch_Close_Ind, Cmplnc_Vrsn FROM HSABC_DEV.ComplianceRequestControl WHERE Project_Cd = 'CMSUNIV' AND Req_Dt_Key = CURRENT_DATE ORDER BY Btch_ID, Src_ID; | J36: One batch per day | K36: Not Run
A37: IN-03 | B37: Ad-hoc requests | C37: No crosswalk needed | D37: Source without a CMS crosswalk row | E37: Insert into ComplianceRequestInTake, then run BATCH_CREATION. INSERT INTO HSABC_DEV.ComplianceRequestInTake (Project_Cd, Table_Nm, Src_ID, Run_Ty, Cmplnc_Vrsn, Rpt_Start_Dt_Key, Rpt_End_Dt_Key, Req_Start_Dt_Key, Req_End_Dt_Key) VALUES ('CMSUNIV', 'ODAG3', '51', 'CMS', '2200', DATE '2026-09-01', DATE '2026-09-30', CURRENT_DATE, CURRENT_DATE); | G37: Airflow DAG OSSTD_CORE_CMS_COMPLIANCE_BATCH_CREATION Trigger DAG w/ config: {"project": "CMSUNIV"} | H37: 1. Check the precondition 2. Prepare the input: Source without a CMS crosswalk row 3. Run the job 4. Run the verification SQL (replace <batch>, <table>) 5. Compare with the expected result and record the outcome | I37: SELECT Intake_ID, Table_Nm, Src_ID, Run_Ty, Req_Start_Dt_Key, Req_End_Dt_Key, Last_Run_Dt_Key FROM HSABC_DEV.ComplianceRequestInTake ORDER BY Intake_ID DESC; SELECT Btch_ID, Src_ID, Run_Ty, Rpt_Start_Dt_Key, Rpt_End_Dt_Key, Req_Dt_Key, Req_Stat, Resolution_Ty, Batch_Close_Ind, Cmplnc_Vrsn FROM HSABC_DEV.ComplianceRequestControl WHERE Project_Cd = 'CMSUNIV' AND Req_Dt_Key = CURRENT_DATE ORDER BY Btch_ID, Src_ID; | J37: Batch still created | K37: Not Run
A38: IN-04 | B38: Ad-hoc requests | C38: Missing config | D38: Source with no file / internal config for the table | E38: Insert into ComplianceRequestInTake, then run BATCH_CREATION. INSERT INTO HSABC_DEV.ComplianceRequestInTake (Project_Cd, Table_Nm, Src_ID, Run_Ty, Cmplnc_Vrsn, Rpt_Start_Dt_Key, Rpt_End_Dt_Key, Req_Start_Dt_Key, Req_End_Dt_Key) VALUES ('CMSUNIV', 'ODAG3', '51', 'CMS', '2200', DATE '2026-09-01', DATE '2026-09-30', CURRENT_DATE, CURRENT_DATE); | F38: INSERT INTO HSABC_DEV.ComplianceRequestInTake (Project_Cd, Table_Nm, Src_ID, Run_Ty, Cmplnc_Vrsn, Rpt_Start_Dt_Key, Rpt_End_Dt_Key, Req_Start_Dt_Key, Req_End_Dt_Key) VALUES ('CMSUNIV', 'ODAG3', '999', 'CMS', '2200', DATE '2026-09-01', DATE '2026-09-30', CURRENT_DATE, CURRENT_DATE); | G38: Airflow DAG OSSTD_CORE_CMS_COMPLIANCE_BATCH_CREATION Trigger DAG w/ config: {"project": "CMSUNIV"} | H38: 1. Check the precondition and run the setup SQL 2. Prepare the input: Source with no file / internal config for the table 3. Run the job 4. Run the verification SQL (replace <batch>, <table>) 5. Compare with the expected result and record the outcome | I38: SELECT Intake_ID, Table_Nm, Src_ID, Run_Ty, Req_Start_Dt_Key, Req_End_Dt_Key, Last_Run_Dt_Key FROM HSABC_DEV.ComplianceRequestInTake ORDER BY Intake_ID DESC; SELECT TOP 20 Event_ID, Event_Ty, Sevrty, Btch_ID, Src_ID, Event_Txt, Notified_Ind FROM HSABC_DEV.CMS_ComplianceExceptionsAudit ORDER BY Event_ID DESC; | J38: INTAKE_FAILED alert; no batch; validate-config INTAKE_REQUEST | K38: Not Run
A39: IN-05 | B39: Ad-hoc requests | C39: Ad hoc held | D39: Load the file | E39: Insert into ComplianceRequestInTake, then run BATCH_CREATION. INSERT INTO HSABC_DEV.ComplianceRequestInTake (Project_Cd, Table_Nm, Src_ID, Run_Ty, Cmplnc_Vrsn, Rpt_Start_Dt_Key, Rpt_End_Dt_Key, Req_Start_Dt_Key, Req_End_Dt_Key) VALUES ('CMSUNIV', 'ODAG3', '51', 'CMS', '2200', DATE '2026-09-01', DATE '2026-09-30', CURRENT_DATE, CURRENT_DATE); | G39: Airflow DAG OSSTD_CORE_CMS_COMPLIANCE_FILE_LOAD Trigger DAG w/ config: {"project": "CMSUNIV"} then Airflow DAG OSSTD_CORE_CMS_COMPLIANCE_EXPORT_LOAD Trigger DAG w/ config: {"project": "CMSUNIV"} | H39: 1. Check the precondition 2. Prepare the input: Load the file 3. Run the job 4. Run the verification SQL (replace <batch>, <table>) 5. Compare with the expected result and record the outcome | I39: SELECT Load_ID, File_Path, Load_Stat, Reject_Rsn_Cd, Rules_Stat, Stg_Rcd_Cnt, Error_Txt, Updated_Dtts FROM HSABC_DEV.ComplianceFileLoad WHERE Btch_ID = '<batch>' ORDER BY Load_ID DESC; SELECT Btch_ID, Src_ID, Req_Stat, Resolution_Ty, Batch_Close_Ind, Reuse_Btch_ID, Rpt_Start_Dt_Key, Rpt_End_Dt_Key FROM HSABC_DEV.ComplianceRequestControl WHERE Btch_ID = '<batch>' ORDER BY Src_ID; | J39: Loaded; SOURCE_LOAD / EXPORT_LOAD list it under held until released | K39: Not Run
A40: IN-06 | B40: Ad-hoc requests | C40: Release | D40: EXPORT_LOAD {"project":"CMSUNIV","run_type":"CMS","release":"true"} | E40: Insert into ComplianceRequestInTake, then run BATCH_CREATION. INSERT INTO HSABC_DEV.ComplianceRequestInTake (Project_Cd, Table_Nm, Src_ID, Run_Ty, Cmplnc_Vrsn, Rpt_Start_Dt_Key, Rpt_End_Dt_Key, Req_Start_Dt_Key, Req_End_Dt_Key) VALUES ('CMSUNIV', 'ODAG3', '51', 'CMS', '2200', DATE '2026-09-01', DATE '2026-09-30', CURRENT_DATE, CURRENT_DATE); | G40: Airflow DAG OSSTD_CORE_CMS_COMPLIANCE_EXPORT_LOAD Trigger DAG w/ config: {"project": "CMSUNIV", "run_type": "CMS", "release": "true"} | H40: 1. Check the precondition 2. Prepare the input: EXPORT_LOAD {"project":"CMSUNIV","run_type":"CMS","release":"true"} 3. Run the job 4. Run the verification SQL (replace <batch>, <table>) 5. Compare with the expected result and record the outcome | I40: SELECT Src_Data_Key, COUNT(*) AS Rows_ FROM CMSUNIV_EXPORT_DEV_T.<table>_EXPORT WHERE Exp_Btch_ID = '<batch>' GROUP BY 1; SELECT c.Src_ID, d.Event_Dtts, d.Event_Ty, d.Load_ID, d.Event_Txt FROM HSABC_DEV.ComplianceRequestFileDetail d JOIN HSABC_DEV.ComplianceRequestControl c ON c.Req_ID = d.Req_ID WHERE c.Btch_ID = '<batch>' ORDER BY c.Src_ID, d.Detail_ID; | J40: Exported; BATCH_RELEASED on the timeline | K40: Not Run
...

Sheet Queries
A1: Query | B1: Purpose | C1: SQL
A2: Q1 | B2: batches of a day (all sources) | C2: SELECT Btch_ID, Src_ID, Run_Ty, Rpt_Start_Dt_Key, Rpt_End_Dt_Key, Req_Dt_Key, Req_Stat, Resolution_Ty, Batch_Close_Ind, Cmplnc_Vrsn FROM HSABC_DEV.ComplianceRequestControl WHERE Project_Cd = 'CMSUNIV' AND Req_Dt_Key = DATE '2026-10-26' ORDER BY Btch_ID, Src_ID;
A3: Q2 | B3: one batch | C3: SELECT * FROM HSABC_DEV.ComplianceRequestControl WHERE Btch_ID = '<batch>' ORDER BY Src_ID;
A4: Q3 | B4: timeline of a batch | C4: SELECT c.Src_ID, d.Event_Dtts, d.Event_Ty, d.Load_ID, d.Event_Txt FROM HSABC_DEV.ComplianceRequestFileDetail d JOIN HSABC_DEV.ComplianceRequestControl c ON c.Req_ID = d.Req_ID WHERE c.Btch_ID = '<batch>' ORDER BY c.Src_ID, d.Detail_ID;
A5: Q4 | B5: loads (files and pulls) of a batch, newest first | C5: SELECT Load_ID, File_Share, File_Path, Load_Stat, Reject_Rsn_Cd, Rules_Stat, Stg_Rcd_Cnt, Error_Txt, Updated_Dtts FROM HSABC_DEV.ComplianceFileLoad WHERE Btch_ID = '<batch>' ORDER BY Load_ID DESC;
A6: Q5 | B6: alerts (audit) of a batch | C6: SELECT Event_ID, Event_Ty, Sevrty, Src_ID, Load_ID, Event_Txt, Notified_Ind, Event_Dtts FROM HSABC_DEV.CMS_ComplianceExceptionsAudit WHERE Btch_ID = '<batch>' ORDER BY Event_ID;
A7: Q6 | B7: staging rows by batch / source / run type / load | C7: SELECT Btch_ID, Src_Data_Key, Run_Ty, AuditDataID, COUNT(*) FROM <staging db>.<table> GROUP BY 1, 2, 3, 4 ORDER BY 1, 2;
A8: Q7 | B8: core rows of a batch | C8: SELECT Src_Data_Key, COUNT(*), MIN(StagingCreateDate), MAX(Load_Dtts) FROM <core db>.<table> WHERE Btch_ID = '<batch>' GROUP BY 1;
A9: Q8 | B9: export rows of a batch | C9: SELECT Src_Data_Key, COUNT(*) FROM CMSUNIV_EXPORT_DEV_T.<table>_EXPORT WHERE Exp_Btch_ID = '<batch>' GROUP BY 1;
A10: Q9 | B10: rules results of a batch | C10: SELECT r.rule_id, r.status, r.run_key FROM HSABC_DEV.gre_results r WHERE r.run_key = '<batch>' ORDER BY 1; SELECT rule_id, run_type, batch_schedule, COUNT(*) FROM HSABC_DEV.gre_exceptions WHERE run_key = '<batch>' AND etl_is_curr_ind = 'Y' GROUP BY 1, 2, 3;
A11: Q10 | B11: locks | C11: SELECT Lock_Key, Owner_ID, Acquired_Dtts, Expires_Dtts FROM HSABC_DEV.ComplianceLock ORDER BY Acquired_Dtts;
A12: Q11 | B12: unsent alerts | C12: SELECT Event_ID, Event_Ty, Btch_ID, Event_Dtts FROM HSABC_DEV.CMS_ComplianceExceptionsAudit WHERE Notified_Ind = 0 ORDER BY Event_ID;
A13: Q12 | B13: framework tables present | C13: SELECT TableName FROM DBC.TablesV WHERE DatabaseName = 'HSABC_DEV' AND (TableName LIKE 'Compliance%' OR TableName = 'CMS_ComplianceExceptionsAudit') ORDER BY 1;

Sheet Prerequisites
A1: # | B1: Item | C1: How to check
A2: P1 | B2: Framework 0.3.67 and rules_engine deployed in the DAGs folder; 9 DAGs visible, no import errors | C2: Airflow UI → DAGs; Browse → DAG import errors empty
A3: P2 | B3: Metadata tables from sql/schema.sql exist in HSABC_DEV (20 tables) | C3: Q12
A4: P3 | B4: CMSUNIV configuration loaded (examples/cmsuniv_setup.sql), run types DLY / WKLY | C4: SELECT Run_Ty, Sched_Cd, SLA_Days FROM HSABC_DEV.ComplianceRunType;
A5: P4 | B5: Staging, core, export tables and export procedures created (examples/cmsuniv_export_dev.sql) | C5: SHOW TABLE on a few
A6: P5 | B6: Airflow Connections: DEV (Teradata), comp_oper_creds (NAS), SQL_CHS, SQL_AZ, SQL_SNPCC, smtp_default | C6: Admin → Connections
A7: P6 | B7: 9 Airflow Variables from examples/cmsuniv_dev/ | C7: Admin → Variables
A8: P7 | B8: Pool gre_rules with 1 slot; Airflow triggerer running | C8: Admin → Pools; airflow jobs check --job-type TriggererJob
A9: P8 | B9: GRE tables (gre_rules, gre_results, gre_exceptions, gre_rule_audit, gre_rule_errors) and CMSUNIV rules | C9: SELECT RULE_GROUP, RULE_VARIANT, COUNT(*) FROM HSABC_DEV.gre_rules WHERE ACT_IND = 1 GROUP BY 1, 2;
A10: P9 | B10: Export feed views EXPORT_FEED_DEV_V.SDO_CMSUNIV_* with a Btch_ID column | C10: SHOW VIEW
A11: P10 | B11: email_recipient mailbox reachable | C11: Send a test email from Airflow

Sheet Test Data
A1: File name: CMSAUTH_<source>_<file type>_22_<run type>_<report start>_<report end>_<YYYYMMDDHHMISS>.txt, e.g. CMSAUTH_CDHDHMO_PYMT_C_22_DLY_20261025_20261025_20261026080000.txt
A3: File | B3: Content
A4: GOOD | B4: Header, 3–5 data rows with valid values, trailer with the right count
A5: EMPTY | B5: Header and trailer only (0 data rows)
A6: BAD_HEADER | B6: One header name changed
A7: BAD_COUNT | B7: Trailer count wrong
A8: BAD_RECORD | B8: One row with a missing field, one with an extra field, one blank line
A9: BAD_VALUE | B9: A value breaking a check (VALUE_IN, DATE_FORMAT, LENGTH)
A10: BAD_TYPE | B10: A value that does not convert to its core column's type (e.g. 13/45/2026 into a DATE column)
A11: BAD_NAME | B11: Name not matching the template (e.g. version 21, unknown run type, bad date)
A12: NO_BATCH | B12: Report dates for which no batch exists
A13: DUP | B13: A copy of GOOD under another timestamp
